<mujoco model="cube3">
    <include file="scene.xml" />
    <extension>
        <plugin plugin="mujoco.elasticity.solid" />
    </extension>
    <worldbody>
        <!-- front face -->
        <body name="v1" pos="0 0 0.1">
            <inertial pos="0 0 0" mass="0.01" diaginertia="1.66667e-05 1.66667e-05 1.66667e-05" />
        </body>
        <body name="v2" pos="1 0 0.1">
            <inertial pos="0 0 0" mass="0.01" diaginertia="1.66667e-05 1.66667e-05 1.66667e-05" />
        </body>
        <body name="v3" pos="0 0 1.1">
            <inertial pos="0 0 0" mass="0.01" diaginertia="1.66667e-05 1.66667e-05 1.66667e-05" />
            <joint name="v3_jx" pos="0 0 0" axis="1 0 0" type="slide" limited="true"
                range="-0.4 0.4" />
            <joint name="v3_jy" pos="0 0 0" axis="0 1 0" type="slide" limited="true"
                range="-0.4 0.4" />
            <joint name="v3_jz" pos="0 0 0" axis="0 0 1" type="slide" limited="true"
                range="-0.4 0.4" />
        </body>

        <body name="v4" pos="1 0 1.1">
            <inertial pos="0 0 0" mass="0.01" diaginertia="1.66667e-05 1.66667e-05 1.66667e-05" />
            <joint name="v4_jx" pos="0 0 0" axis="1 0 0" type="slide" limited="true"
                range="-0.4 0.4" />
            <joint name="v4_jy" pos="0 0 0" axis="0 1 0" type="slide" limited="true"
                range="-0.4 0.4" />
            <joint name="v4_jz" pos="0 0 0" axis="0 0 1" type="slide" limited="true"
                range="-0.4 0.4" />
        </body>

        <!-- left face -->

        <body name="v5" pos="0 1 1.1">
            <inertial pos="0 0 0" mass="0.01" diaginertia="1.66667e-05 1.66667e-05 1.66667e-05" />
            <joint name="v5_jx" pos="0 0 0" axis="1 0 0" type="slide" limited="true"
                range="-0.4 0.4" />
            <joint name="v5_jy" pos="0 0 0" axis="0 1 0" type="slide" limited="true"
                range="-0.4 0.4" />
            <joint name="v5_jz" pos="0 0 0" axis="0 0 1" type="slide" limited="true"
                range="-0.4 0.4" />
        </body>

        <body name="v6" pos="0 1 0.1">
            <inertial pos="0 0 0" mass="0.01" diaginertia="1.66667e-05 1.66667e-05 1.66667e-05" />
        </body>


        <body name="v8" pos="1 1 0.1">
            <inertial pos="0 0 0" mass="0.01" diaginertia="1.66667e-05 1.66667e-05 1.66667e-05" />
        </body>

        <body name="v9" pos="1 1 1.1">
            <inertial pos="0 0 0" mass="0.01" diaginertia="1.66667e-05 1.66667e-05 1.66667e-05" />
            <joint name="v9_jx" pos="0 0 0" axis="1 0 0" type="slide" limited="true"
                range="-0.4 0.4" />
            <joint name="v9_jy" pos="0 0 0" axis="0 1 0" type="slide" limited="true"
                range="-0.4 0.4" />
            <joint name="v9_jz" pos="0 0 0" axis="0 0 1" type="slide" limited="true"
                range="-0.4 0.4" />
        </body>


    </worldbody>

    <deformable>
        <flex name="body1" dim="2" body="v1 v2 v3" vertex="0 0 0 0 0 0 0 0 0"
            element="0 1 2" rgba="0 0 0.4 0.9" />
        <flex name="body2" dim="2" body="v2 v4 v3" vertex="0 0 0 0 0 0 0 0 0"
            element="0 1 2" rgba="0 0 0.9 0.9" />
        <flex name="body3" dim="2" body="v5 v3 v1" vertex="0 0 0 0 0 0 0 0 0"
            element="0 1 2" rgba="0 0.4 0 0.9" />
        <flex name="body4" dim="2" body="v6 v1 v5" vertex="0 0 0 0 0 0 0 0 0"
            element="0 1 2" rgba="0 0.9 0 0.9" />
        <flex name="body5" dim="2" body="v2 v8 v4" vertex="0 0 0 0 0 0 0 0 0"
            element="0 1 2" rgba="0.5 0.7 0.9 0.9" />
        <flex name="body6" dim="2" body="v8 v9 v4" vertex="0 0 0 0 0 0 0 0 0"
            element="0 1 2" rgba="0.5 0.9 0.9 0.9" />
        <flex name="body7" dim="2" body="v8 v6 v9" vertex="0 0 0 0 0 0 0 0 0"
            element="0 1 2" rgba="0.5 0 0.9 0.9" />
        <flex name="body8" dim="2" body="v6 v5 v9" vertex="0 0 0 0 0 0 0 0 0"
            element="0 1 2" rgba="0.5 0 0.5 0.9" />


    </deformable>
    <equality>
        <flex flex="body1" />
        <flex flex="body2" />
        <flex flex="body3" />
        <flex flex="body4" />
        <flex flex="body5" />
        <flex flex="body6" />
        <flex flex="body7" />
        <flex flex="body8" />
        <joint joint1="v5_jx" joint2="v4_jx" polycoef="0 -1 0 0 0" />
        <joint joint1="v5_jx" joint2="v9_jx" polycoef="0 1 0 0 0" />
    </equality>
    <actuator>
        <position name="x-force" joint="v4_jx" kp="500" />
        <position name="z_force" joint="v4_jz" kp="500" />
    </actuator>
</mujoco>